<sdf version='1.7'>
  <world name='default'>
    <light name='sun' type='directional'>
      <cast_shadows>0</cast_shadows>
      <pose>0 0 10 0 -0 0</pose>
      <diffuse>1 1 1 1</diffuse>
      <specular>0.9 0.9 0.9 1</specular>
      <attenuation>
        <range>1000</range>
        <constant>0.9</constant>
        <linear>0.01</linear>
        <quadratic>0.001</quadratic>
      </attenuation>
      <direction>-0.5 0.1 -0.9</direction>
      <spot>
        <inner_angle>0</inner_angle>
        <outer_angle>0</outer_angle>
        <falloff>0</falloff>
      </spot>
    </light>
    <model name='ground_plane'>
      <static>1</static>
      <link name='link'>
        <collision name='collision'>
          <geometry>
            <plane>
              <normal>0 0 1</normal>
              <size>100 100</size>
            </plane>
          </geometry>
          <surface>
            <friction>
              <ode>
                <mu>100</mu>
                <mu2>50</mu2>
              </ode>
              <torsional>
                <ode/>
              </torsional>
            </friction>
            <contact>
              <ode/>
            </contact>
            <bounce/>
          </surface>
          <max_contacts>10</max_contacts>
        </collision>
        <visual name='visual'>
          <cast_shadows>0</cast_shadows>
          <geometry>
            <plane>
              <normal>0 0 1</normal>
              <size>100 100</size>
            </plane>
          </geometry>
          <material>
            <script>
              <uri>file://media/materials/scripts/gazebo.material</uri>
              <name>Gazebo/Grey</name>
            </script>
          </material>
        </visual>
        <self_collide>0</self_collide>
        <enable_wind>0</enable_wind>
        <kinematic>0</kinematic>
      </link>
    </model>
    <gravity>0 0 -9.8</gravity>
    <magnetic_field>6e-06 2.3e-05 -4.2e-05</magnetic_field>
    <atmosphere type='adiabatic'/>
    <physics type='ode'>
      <max_step_size>0.001</max_step_size>
      <real_time_factor>1</real_time_factor>
      <real_time_update_rate>1000</real_time_update_rate>
    </physics>
    <scene>
      <ambient>0.4 0.4 0.4 1</ambient>
      <background>1 1 1 1</background>
      <shadows>1</shadows>
    </scene>
    <wind/>
    <spherical_coordinates>
      <surface_model>EARTH_WGS84</surface_model>
      <latitude_deg>0</latitude_deg>
      <longitude_deg>0</longitude_deg>
      <elevation>0</elevation>
      <heading_deg>0</heading_deg>
    </spherical_coordinates>
    <model name='track_2'>
      <link name='link_0'>
        <inertial>
          <mass>1</mass>
          <inertia>
            <ixx>0.166667</ixx>
            <ixy>0</ixy>
            <ixz>0</ixz>
            <iyy>0.166667</iyy>
            <iyz>0</iyz>
            <izz>0.166667</izz>
          </inertia>
          <pose>0 0 0 0 -0 0</pose>
        </inertial>
        <pose>-0 -0 6e-06 0 -0 0</pose>
        <gravity>1</gravity>
        <self_collide>0</self_collide>
        <kinematic>0</kinematic>
        <enable_wind>0</enable_wind>
        <visual name='visual'>
          <pose>0 0 -0.03 0 -0 0</pose>
          <geometry>
            <box>
              <size>22.5 40 0.05</size>
            </box>
          </geometry>
          <material>
            <lighting>1</lighting>
            <script>
              <uri>model://line_following_rover/urdf/track_2/materials/scripts</uri>
              <uri>model://line_following_rover/urdf/track_2/materials/textures</uri>
              <name>track_2/Diffuse</name>
            </script>
            <shader type='pixel'>
              <normal_map>__default__</normal_map>
            </shader>
            <ambient>0.3 0.3 0.3 1</ambient>
            <diffuse>0.7 0.7 0.7 1</diffuse>
            <specular>0.01 0.01 0.01 1</specular>
            <emissive>0 0 0 1</emissive>
          </material>
          <transparency>0</transparency>
          <cast_shadows>1</cast_shadows>
        </visual>
        <collision name='collision'>
          <laser_retro>0</laser_retro>
          <max_contacts>10</max_contacts>
          <pose>0 0 0 0 -0 0</pose>
          <geometry>
            <box>
              <size>22.5 40 0.05</size>
            </box>
          </geometry>
          <surface>
            <friction>
              <ode>
                <mu>1.7</mu>
                <mu2>1.7</mu2>
                <fdir1>0 0 0</fdir1>
                <slip1>0</slip1>
                <slip2>0</slip2>
              </ode>
              <torsional>
                <coefficient>1.7</coefficient>
                <patch_radius>0.1</patch_radius>
                <surface_radius>0.1</surface_radius>
                <use_patch_radius>1</use_patch_radius>
                <ode>
                  <slip>0</slip>
                </ode>
              </torsional>
            </friction>
            <bounce>
              <restitution_coefficient>0</restitution_coefficient>
              <threshold>1e+06</threshold>
            </bounce>
            <contact>
              <collide_without_contact>0</collide_without_contact>
              <collide_without_contact_bitmask>1</collide_without_contact_bitmask>
              <collide_bitmask>1</collide_bitmask>
              <ode>
                <soft_cfm>0</soft_cfm>
                <soft_erp>0.2</soft_erp>
                <kp>1e+13</kp>
                <kd>1</kd>
                <max_vel>0.01</max_vel>
                <min_depth>0</min_depth>
              </ode>
              <bullet>
                <split_impulse>1</split_impulse>
                <split_impulse_penetration_threshold>-0.01</split_impulse_penetration_threshold>
                <soft_cfm>0</soft_cfm>
                <soft_erp>0.2</soft_erp>
                <kp>1e+13</kp>
                <kd>1</kd>
              </bullet>
            </contact>
          </surface>
        </collision>
      </link>
      <static>1</static>
      <allow_auto_disable>1</allow_auto_disable>
      <pose>-1.31893 -0.619139 0 0 -0 0</pose>
    </model>
    <state world_name='default'>
      <sim_time>1445 298000000</sim_time>
      <real_time>180 337049313</real_time>
      <wall_time>1732439560 606714713</wall_time>
      <iterations>179982</iterations>
      <model name='ground_plane'>
        <pose>0 0 0 0 -0 0</pose>
        <scale>1 1 1</scale>
        <link name='link'>
          <pose>0 0 0 0 -0 0</pose>
          <velocity>0 0 0 0 -0 0</velocity>
          <acceleration>0 0 0 0 -0 0</acceleration>
          <wrench>0 0 0 0 -0 0</wrench>
        </link>
      </model>
      <model name='px4vision'>
        <pose>0.52109 -17.6846 0.129519 -2.1e-05 0.000196 -0.018407</pose>
        <scale>1 1 1</scale>
        <link name='/imu_link'>
          <pose>0.52109 -17.6846 0.129519 -2.1e-05 0.000196 -0.018407</pose>
          <velocity>-0 -0 -0 -0 -0 -0</velocity>
          <acceleration>-0 0 0 -0.000123 2e-06 -0</acceleration>
          <wrench>-0 0 0 0 -0 0</wrench>
        </link>
        <link name='base_link'>
          <pose>0.52109 -17.6846 0.129519 -2.1e-05 0.000196 -0.018407</pose>
          <velocity>-0 -0 -0 0 -0 0</velocity>
          <acceleration>-0 0 0 0 -0 0</acceleration>
          <wrench>-0 0 0 0 -0 0</wrench>
        </link>
        <link name='depth_camera::link'>
          <pose>0.616071 -17.6863 0.114501 -4.3e-05 1.0502 -0.018444</pose>
          <velocity>-0 -0 -0 0 -0 0</velocity>
          <acceleration>0 -0 -0 -1e-06 0 0</acceleration>
          <wrench>0 -0 -0 0 -0 0</wrench>
        </link>
        <link name='gps::link'>
          <pose>0.521113 -17.6846 0.249519 -2.1e-05 0.000196 -0.018407</pose>
          <velocity>-0 -0 -0 0 -0 0</velocity>
          <acceleration>-0 -0 -0 0 -0 0</acceleration>
          <wrench>-0 -0 -0 0 -0 0</wrench>
        </link>
        <link name='rotor_0'>
          <pose>0.61261 -17.7933 0.159503 5.2e-05 -0.00019 2.96574</pose>
          <velocity>-0 -0 -0 0 -0 0</velocity>
          <acceleration>-0 -0 -0 0 -0 0</acceleration>
          <wrench>-0 -0 -0 0 -0 0</wrench>
        </link>
        <link name='rotor_1'>
          <pose>0.429581 -17.5759 0.159535 0.000106 0.000164 0.668749</pose>
          <velocity>-0 -0 -0 0 -0 0</velocity>
          <acceleration>-0 0 0 2e-06 1e-06 0</acceleration>
          <wrench>-0 0 0 0 -0 0</wrench>
        </link>
        <link name='rotor_2'>
          <pose>0.616549 -17.5793 0.159499 -6.5e-05 0.000186 -0.247583</pose>
          <velocity>-0 -0 -0 0 -0 0</velocity>
          <acceleration>-0 -0 0 0 -0 0</acceleration>
          <wrench>-0 -0 0 0 -0 0</wrench>
        </link>
        <link name='rotor_3'>
          <pose>0.425642 -17.7899 0.15954 1.9e-05 0.000196 0.186065</pose>
          <velocity>-0 -0 -0 0 -0 0</velocity>
          <acceleration>-0 0 -0 0 -0 0</acceleration>
          <wrench>-0 0 -0 0 -0 0</wrench>
        </link>
      </model>
      <model name='rover_proto_A1_gps'>
        <pose>1.58209 -17.6657 0.19497 -5e-06 -3.9e-05 -0.021821</pose>
        <scale>1 1 1</scale>
        <link name='Chassis'>
          <pose>1.58209 -17.6657 0.19497 -5e-06 -3.9e-05 -0.021821</pose>
          <velocity>4.5e-05 0.000503 -0.004336 -0.023065 0.00059 -7.3e-05</velocity>
          <acceleration>0.01405 0.136737 -9.71516 -0.79558 0.162096 -0.09449</acceleration>
          <wrench>0.254219 2.4741 -175.785 0 -0 0</wrench>
        </link>
        <link name='Wheel_1_Link'>
          <pose>1.92604 -17.8883 0.154984 1.57085 -0.587233 -0.021853</pose>
          <velocity>1.7e-05 -0.001158 0.000864 -0.052444 0.000241 2e-05</velocity>
          <acceleration>0.004494 -1.10713 -10.0262 -2.79836 0.527871 0.036202</acceleration>
          <wrench>0.002053 -0.505756 -4.58015 0 -0 0</wrench>
        </link>
        <link name='Wheel_2_Link'>
          <pose>1.93542 -17.4584 0.154981 1.57072 0.141177 -0.021832</pose>
          <velocity>5.8e-05 -6.8e-05 -0.009149 -0.005753 0.000187 0.000101</velocity>
          <acceleration>0.038506 -0.00709 -9.65891 -0.228153 -0.006351 0.177141</acceleration>
          <wrench>0.01759 -0.003239 -4.41236 0 -0 0</wrench>
        </link>
        <link name='Wheel_3_Link'>
          <pose>1.23559 -17.4431 0.154954 1.57072 -0.465862 -0.021787</pose>
          <velocity>6.4e-05 -3.6e-05 -0.009019 -0.006508 0.000201 -6.5e-05</velocity>
          <acceleration>0.046942 0.019016 -9.55684 -0.915204 0.051691 -0.114647</acceleration>
          <wrench>0.021444 0.008687 -4.36573 0 -0 0</wrench>
        </link>
        <link name='Wheel_4_Link'>
          <pose>1.2262 -17.873 0.154957 1.57084 0.064968 -0.021819</pose>
          <velocity>2.8e-05 -0.000977 0.000815 -0.046011 0.000371 1.1e-05</velocity>
          <acceleration>0.016347 -0.873353 -9.8709 2.97479 0.556615 0.019131</acceleration>
          <wrench>0.007467 -0.398963 -4.5092 0 -0 0</wrench>
        </link>
      </model>
      <model name='track_2'>
        <pose>2.59865 -1.95957 0.049994 0 0 -0.004983</pose>
        <scale>1 1 1</scale>
        <link name='link_0'>
          <pose>2.59865 -1.95957 0.05 0 0 -0.004983</pose>
          <velocity>0 0 0 0 -0 0</velocity>
          <acceleration>0 0 0 0 -0 0</acceleration>
          <wrench>0 0 0 0 -0 0</wrench>
        </link>
      </model>
      <light name='sun'>
        <pose>0 0 10 0 -0 0</pose>
      </light>
      <light name='user_directional_light_0'>
        <pose>3.28777 -7.89594 1 0 -0 0</pose>
      </light>
      <light name='user_directional_light_1'>
        <pose>-2.70099 1.56133 1 0 -0 0</pose>
      </light>
      <light name='user_directional_light_2'>
        <pose>5.65592 4.53366 1 0 -0 0</pose>
      </light>
      <light name='user_directional_light_3'>
        <pose>7.02737 -2.79913 1 0 -0 0</pose>
      </light>
      <light name='user_directional_light_4'>
        <pose>-2.73559 -5.19311 1 0 -0 0</pose>
      </light>
      <light name='user_directional_light_5'>
        <pose>10.6409 -2.37644 1 0 -0 0</pose>
      </light>
      <light name='user_directional_light_6'>
        <pose>-2.67274 15.5048 1 0 -0 0</pose>
      </light>
    </state>
    <gui fullscreen='0'>
      <camera name='user_camera'>
        <pose>-5.61928 -17.5911 6.28659 0 0.781798 0.06799</pose>
        <view_controller>orbit</view_controller>
        <projection_type>perspective</projection_type>
      </camera>
    </gui>
    <audio>
      <device>default</device>
    </audio>
    <light name='user_directional_light_0' type='directional'>
      <pose>3.28777 -7.89594 1 0 -0 0</pose>
      <diffuse>0.5 0.5 0.5 1</diffuse>
      <specular>0.1 0.1 0.1 1</specular>
      <direction>0.1 0.1 -0.9</direction>
      <attenuation>
        <range>20</range>
        <constant>0.5</constant>
        <linear>0.01</linear>
        <quadratic>0.001</quadratic>
      </attenuation>
      <cast_shadows>1</cast_shadows>
      <spot>
        <inner_angle>0</inner_angle>
        <outer_angle>0</outer_angle>
        <falloff>0</falloff>
      </spot>
    </light>
    <light name='user_directional_light_1' type='directional'>
      <pose>-2.70099 1.56133 1 0 -0 0</pose>
      <diffuse>0.5 0.5 0.5 1</diffuse>
      <specular>0.1 0.1 0.1 1</specular>
      <direction>0.1 0.1 -0.9</direction>
      <attenuation>
        <range>20</range>
        <constant>0.5</constant>
        <linear>0.01</linear>
        <quadratic>0.001</quadratic>
      </attenuation>
      <cast_shadows>1</cast_shadows>
      <spot>
        <inner_angle>0</inner_angle>
        <outer_angle>0</outer_angle>
        <falloff>0</falloff>
      </spot>
    </light>
    <light name='user_directional_light_2' type='directional'>
      <pose>5.65592 4.53366 1 0 -0 0</pose>
      <diffuse>0.5 0.5 0.5 1</diffuse>
      <specular>0.1 0.1 0.1 1</specular>
      <direction>0.1 0.1 -0.9</direction>
      <attenuation>
        <range>20</range>
        <constant>0.5</constant>
        <linear>0.01</linear>
        <quadratic>0.001</quadratic>
      </attenuation>
      <cast_shadows>1</cast_shadows>
      <spot>
        <inner_angle>0</inner_angle>
        <outer_angle>0</outer_angle>
        <falloff>0</falloff>
      </spot>
    </light>
    <light name='user_directional_light_3' type='directional'>
      <pose>7.02737 -2.79913 1 0 -0 0</pose>
      <diffuse>0.5 0.5 0.5 1</diffuse>
      <specular>0.1 0.1 0.1 1</specular>
      <direction>0.1 0.1 -0.9</direction>
      <attenuation>
        <range>20</range>
        <constant>0.5</constant>
        <linear>0.01</linear>
        <quadratic>0.001</quadratic>
      </attenuation>
      <cast_shadows>1</cast_shadows>
      <spot>
        <inner_angle>0</inner_angle>
        <outer_angle>0</outer_angle>
        <falloff>0</falloff>
      </spot>
    </light>
    <light name='user_directional_light_4' type='directional'>
      <pose>-2.73559 -5.19311 1 0 -0 0</pose>
      <diffuse>0.5 0.5 0.5 1</diffuse>
      <specular>0.1 0.1 0.1 1</specular>
      <direction>0.1 0.1 -0.9</direction>
      <attenuation>
        <range>20</range>
        <constant>0.5</constant>
        <linear>0.01</linear>
        <quadratic>0.001</quadratic>
      </attenuation>
      <cast_shadows>1</cast_shadows>
      <spot>
        <inner_angle>0</inner_angle>
        <outer_angle>0</outer_angle>
        <falloff>0</falloff>
      </spot>
    </light>
    <light name='user_directional_light_5' type='directional'>
      <pose>10.6409 -2.37644 1 0 -0 0</pose>
      <diffuse>0.5 0.5 0.5 1</diffuse>
      <specular>0.1 0.1 0.1 1</specular>
      <direction>0.1 0.1 -0.9</direction>
      <attenuation>
        <range>20</range>
        <constant>0.5</constant>
        <linear>0.01</linear>
        <quadratic>0.001</quadratic>
      </attenuation>
      <cast_shadows>1</cast_shadows>
      <spot>
        <inner_angle>0</inner_angle>
        <outer_angle>0</outer_angle>
        <falloff>0</falloff>
      </spot>
    </light>
    <light name='user_directional_light_6' type='directional'>
      <pose>-2.67274 15.5048 1 0 -0 0</pose>
      <diffuse>0.5 0.5 0.5 1</diffuse>
      <specular>0.1 0.1 0.1 1</specular>
      <direction>0.1 0.1 -0.9</direction>
      <attenuation>
        <range>20</range>
        <constant>0.5</constant>
        <linear>0.01</linear>
        <quadratic>0.001</quadratic>
      </attenuation>
      <cast_shadows>1</cast_shadows>
      <spot>
        <inner_angle>0</inner_angle>
        <outer_angle>0</outer_angle>
        <falloff>0</falloff>
      </spot>
    </light>
    <model name='px4vision'>
      <link name='base_link'>
        <pose>0 0 0 0 -0 0</pose>
        <inertial>
          <pose>0 0 0 0 -0 0</pose>
          <mass>1.5</mass>
          <inertia>
            <ixx>0.029125</ixx>
            <ixy>0</ixy>
            <ixz>0</ixz>
            <iyy>0.029125</iyy>
            <iyz>0</iyz>
            <izz>0.055225</izz>
          </inertia>
        </inertial>
        <collision name='base_link_inertia_collision'>
          <pose>0 0 0 0 -0 0</pose>
          <geometry>
            <box>
              <size>0.47 0.47 0.11</size>
            </box>
          </geometry>
          <surface>
            <contact>
              <ode>
                <min_depth>0.001</min_depth>
                <max_vel>0</max_vel>
              </ode>
            </contact>
            <friction>
              <ode/>
              <torsional>
                <ode/>
              </torsional>
            </friction>
            <bounce/>
          </surface>
          <max_contacts>10</max_contacts>
        </collision>
        <visual name='base_link_inertia_visual'>
          <pose>0 0 0 1.5707 0 -0.01</pose>
          <geometry>
            <mesh>
              <scale>0.001 0.001 0.001</scale>
              <uri>model://px4vision/meshes/body.dae</uri>
            </mesh>
          </geometry>
          <material>
            <script>
              <name>Gazebo/DarkGrey</name>
              <uri>file://media/materials/scripts/gazebo.material</uri>
            </script>
          </material>
        </visual>
        <gravity>1</gravity>
        <velocity_decay/>
        <self_collide>0</self_collide>
        <enable_wind>0</enable_wind>
        <kinematic>0</kinematic>
      </link>
      <link name='/imu_link'>
        <pose>0 0 0 0 -0 0</pose>
        <inertial>
          <pose>0 0 0 0 -0 0</pose>
          <mass>0.015</mass>
          <inertia>
            <ixx>1e-05</ixx>
            <ixy>0</ixy>
            <ixz>0</ixz>
            <iyy>1e-05</iyy>
            <iyz>0</iyz>
            <izz>1e-05</izz>
          </inertia>
        </inertial>
        <self_collide>0</self_collide>
        <enable_wind>0</enable_wind>
        <kinematic>0</kinematic>
      </link>
      <joint name='/imu_joint' type='revolute'>
        <child>/imu_link</child>
        <parent>base_link</parent>
        <axis>
          <xyz expressed_in='__model__'>1 0 0</xyz>
          <limit>
            <lower>0</lower>
            <upper>0</upper>
            <effort>0</effort>
            <velocity>0</velocity>
          </limit>
          <dynamics>
            <spring_reference>0</spring_reference>
            <spring_stiffness>0</spring_stiffness>
          </dynamics>
        </axis>
      </joint>
      <link name='rotor_0'>
        <pose>0.0935 -0.107 0.03 0 -0 0</pose>
        <inertial>
          <pose>0 0 0 0 -0 0</pose>
          <mass>0.005</mass>
          <inertia>
            <ixx>9.75e-07</ixx>
            <ixy>0</ixy>
            <ixz>0</ixz>
            <iyy>0.000273104</iyy>
            <iyz>0</iyz>
            <izz>0.000274004</izz>
          </inertia>
        </inertial>
        <collision name='rotor_0_collision'>
          <pose>0 0 0 0 -0 0</pose>
          <geometry>
            <cylinder>
              <length>0.005</length>
              <radius>0.128</radius>
            </cylinder>
          </geometry>
          <surface>
            <contact>
              <ode/>
            </contact>
            <friction>
              <ode/>
              <torsional>
                <ode/>
              </torsional>
            </friction>
            <bounce/>
          </surface>
          <max_contacts>10</max_contacts>
        </collision>
        <visual name='rotor_0_visual'>
          <pose>0 0 0 0 -0 0</pose>
          <geometry>
            <mesh>
              <scale>0.6 0.6 0.6</scale>
              <uri>model://iris/meshes/iris_prop_ccw.dae</uri>
            </mesh>
          </geometry>
          <material>
            <script>
              <name>Gazebo/Blue</name>
              <uri>file://media/materials/scripts/gazebo.material</uri>
            </script>
          </material>
        </visual>
        <gravity>1</gravity>
        <velocity_decay/>
        <self_collide>0</self_collide>
        <enable_wind>0</enable_wind>
        <kinematic>0</kinematic>
      </link>
      <joint name='rotor_0_joint' type='revolute'>
        <child>rotor_0</child>
        <parent>base_link</parent>
        <axis>
          <xyz expressed_in='__model__'>0 0 1</xyz>
          <limit>
            <lower>-1e+16</lower>
            <upper>1e+16</upper>
          </limit>
          <dynamics>
            <spring_reference>0</spring_reference>
            <spring_stiffness>0</spring_stiffness>
          </dynamics>
        </axis>
      </joint>
      <link name='rotor_1'>
        <pose>-0.0935 0.107 0.03 0 -0 0</pose>
        <inertial>
          <pose>0 0 0 0 -0 0</pose>
          <mass>0.005</mass>
          <inertia>
            <ixx>9.75e-07</ixx>
            <ixy>0</ixy>
            <ixz>0</ixz>
            <iyy>0.000273104</iyy>
            <iyz>0</iyz>
            <izz>0.000274004</izz>
          </inertia>
        </inertial>
        <collision name='rotor_1_collision'>
          <pose>0 0 0 0 -0 0</pose>
          <geometry>
            <cylinder>
              <length>0.005</length>
              <radius>0.128</radius>
            </cylinder>
          </geometry>
          <surface>
            <contact>
              <ode/>
            </contact>
            <friction>
              <ode/>
              <torsional>
                <ode/>
              </torsional>
            </friction>
            <bounce/>
          </surface>
          <max_contacts>10</max_contacts>
        </collision>
        <visual name='rotor_1_visual'>
          <pose>0 0 0 0 -0 0</pose>
          <geometry>
            <mesh>
              <scale>0.6 0.6 0.6</scale>
              <uri>model://iris/meshes/iris_prop_ccw.dae</uri>
            </mesh>
          </geometry>
          <material>
            <script>
              <name>Gazebo/DarkGrey</name>
              <uri>file://media/materials/scripts/gazebo.material</uri>
            </script>
          </material>
        </visual>
        <gravity>1</gravity>
        <velocity_decay/>
        <self_collide>0</self_collide>
        <enable_wind>0</enable_wind>
        <kinematic>0</kinematic>
      </link>
      <joint name='rotor_1_joint' type='revolute'>
        <child>rotor_1</child>
        <parent>base_link</parent>
        <axis>
          <xyz expressed_in='__model__'>0 0 1</xyz>
          <limit>
            <lower>-1e+16</lower>
            <upper>1e+16</upper>
          </limit>
          <dynamics>
            <spring_reference>0</spring_reference>
            <spring_stiffness>0</spring_stiffness>
          </dynamics>
        </axis>
      </joint>
      <link name='rotor_2'>
        <pose>0.0935 0.107 0.03 0 -0 0</pose>
        <inertial>
          <pose>0 0 0 0 -0 0</pose>
          <mass>0.005</mass>
          <inertia>
            <ixx>9.75e-07</ixx>
            <ixy>0</ixy>
            <ixz>0</ixz>
            <iyy>0.000273104</iyy>
            <iyz>0</iyz>
            <izz>0.000274004</izz>
          </inertia>
        </inertial>
        <collision name='rotor_2_collision'>
          <pose>0 0 0 0 -0 0</pose>
          <geometry>
            <cylinder>
              <length>0.005</length>
              <radius>0.128</radius>
            </cylinder>
          </geometry>
          <surface>
            <contact>
              <ode/>
            </contact>
            <friction>
              <ode/>
              <torsional>
                <ode/>
              </torsional>
            </friction>
            <bounce/>
          </surface>
          <max_contacts>10</max_contacts>
        </collision>
        <visual name='rotor_2_visual'>
          <pose>0 0 0 0 -0 0</pose>
          <geometry>
            <mesh>
              <scale>0.6 0.6 0.6</scale>
              <uri>model://iris/meshes/iris_prop_cw.dae</uri>
            </mesh>
          </geometry>
          <material>
            <script>
              <name>Gazebo/Blue</name>
              <uri>file://media/materials/scripts/gazebo.material</uri>
            </script>
          </material>
        </visual>
        <gravity>1</gravity>
        <velocity_decay/>
        <self_collide>0</self_collide>
        <enable_wind>0</enable_wind>
        <kinematic>0</kinematic>
      </link>
      <joint name='rotor_2_joint' type='revolute'>
        <child>rotor_2</child>
        <parent>base_link</parent>
        <axis>
          <xyz expressed_in='__model__'>0 0 1</xyz>
          <limit>
            <lower>-1e+16</lower>
            <upper>1e+16</upper>
          </limit>
          <dynamics>
            <spring_reference>0</spring_reference>
            <spring_stiffness>0</spring_stiffness>
          </dynamics>
        </axis>
      </joint>
      <link name='rotor_3'>
        <pose>-0.0935 -0.107 0.03 0 -0 0</pose>
        <inertial>
          <pose>0 0 0 0 -0 0</pose>
          <mass>0.005</mass>
          <inertia>
            <ixx>9.75e-07</ixx>
            <ixy>0</ixy>
            <ixz>0</ixz>
            <iyy>0.000273104</iyy>
            <iyz>0</iyz>
            <izz>0.000274004</izz>
          </inertia>
        </inertial>
        <collision name='rotor_3_collision'>
          <pose>0 0 0 0 -0 0</pose>
          <geometry>
            <cylinder>
              <length>0.005</length>
              <radius>0.128</radius>
            </cylinder>
          </geometry>
          <surface>
            <contact>
              <ode/>
            </contact>
            <friction>
              <ode/>
              <torsional>
                <ode/>
              </torsional>
            </friction>
            <bounce/>
          </surface>
          <max_contacts>10</max_contacts>
        </collision>
        <visual name='rotor_3_visual'>
          <pose>0 0 0 0 -0 0</pose>
          <geometry>
            <mesh>
              <scale>0.6 0.6 0.6</scale>
              <uri>model://iris/meshes/iris_prop_cw.dae</uri>
            </mesh>
          </geometry>
          <material>
            <script>
              <name>Gazebo/DarkGrey</name>
              <uri>file://media/materials/scripts/gazebo.material</uri>
            </script>
          </material>
        </visual>
        <gravity>1</gravity>
        <velocity_decay/>
        <self_collide>0</self_collide>
        <enable_wind>0</enable_wind>
        <kinematic>0</kinematic>
      </link>
      <joint name='rotor_3_joint' type='revolute'>
        <child>rotor_3</child>
        <parent>base_link</parent>
        <axis>
          <xyz expressed_in='__model__'>0 0 1</xyz>
          <limit>
            <lower>-1e+16</lower>
            <upper>1e+16</upper>
          </limit>
          <dynamics>
            <spring_reference>0</spring_reference>
            <spring_stiffness>0</spring_stiffness>
          </dynamics>
        </axis>
      </joint>
      <frame name='gps::__model__' attached_to='gps::link'>
        <pose relative_to='__model__'>0 0 0.12 0 -0 0</pose>
      </frame>
      <link name='gps::link'>
        <pose relative_to='gps::__model__'>0 0 0 0 -0 0</pose>
        <inertial>
          <pose>0 0 0 0 -0 0</pose>
          <mass>0.015</mass>
          <inertia>
            <ixx>1e-05</ixx>
            <ixy>0</ixy>
            <ixz>0</ixz>
            <iyy>1e-05</iyy>
            <iyz>0</iyz>
            <izz>1e-05</izz>
          </inertia>
        </inertial>
        <visual name='visual'>
          <geometry>
            <cylinder>
              <radius>0.01</radius>
              <length>0.002</length>
            </cylinder>
          </geometry>
          <material>
            <script>
              <name>Gazebo/Black</name>
              <uri>__default__</uri>
            </script>
          </material>
        </visual>
        <sensor name='gps' type='gps'>
          <pose>0 0 0 0 -0 0</pose>
          <update_rate>5</update_rate>
          <always_on>1</always_on>
          <visualize>0</visualize>
          <plugin name='gps_plugin' filename='libgazebo_gps_plugin.so'>
            <robotNamespace/>
            <gpsNoise>1</gpsNoise>
            <gpsXYRandomWalk>2.0</gpsXYRandomWalk>
            <gpsZRandomWalk>4.0</gpsZRandomWalk>
            <gpsXYNoiseDensity>2.0e-4</gpsXYNoiseDensity>
            <gpsZNoiseDensity>4.0e-4</gpsZNoiseDensity>
            <gpsVXYNoiseDensity>0.2</gpsVXYNoiseDensity>
            <gpsVZNoiseDensity>0.4</gpsVZNoiseDensity>
          </plugin>
          <gps/>
        </sensor>
        <self_collide>0</self_collide>
        <enable_wind>0</enable_wind>
        <kinematic>0</kinematic>
      </link>
      <joint name='gps_joint' type='fixed'>
        <child>gps::link</child>
        <parent>base_link</parent>
      </joint>
      <frame name='depth_camera::__model__' attached_to='depth_camera::link'>
        <pose relative_to='__model__'>0.095 0 -0.015 0 1.05 0</pose>
      </frame>
      <link name='depth_camera::link'>
        <inertial>
          <pose>0.01 0.025 0.025 0 -0 0</pose>
          <mass>0.01</mass>
          <inertia>
            <ixx>4.15e-06</ixx>
            <ixy>0</ixy>
            <ixz>0</ixz>
            <iyy>2.407e-06</iyy>
            <iyz>0</iyz>
            <izz>2.407e-06</izz>
          </inertia>
        </inertial>
        <visual name='visual'>
          <pose>0 0 0 0 -0 0</pose>
          <geometry>
            <mesh>
              <uri>model://realsense_camera/meshes/realsense.dae</uri>
            </mesh>
          </geometry>
        </visual>
        <sensor name='depth_camera' type='depth'>
          <always_on>1</always_on>
          <update_rate>10</update_rate>
          <camera name='camera_name'>
            <horizontal_fov>1.50098</horizontal_fov>
            <image>
              <format>R8G8B8</format>
              <width>848</width>
              <height>480</height>
            </image>
            <clip>
              <near>0.001</near>
              <far>65.535</far>
            </clip>
            <distortion>
              <k1>0</k1>
              <k2>0</k2>
              <k3>0</k3>
              <p1>0</p1>
              <p2>0</p2>
              <center>0.5 0.5</center>
            </distortion>
          </camera>
          <plugin name='camera_controller' filename='libgazebo_ros_camera.so'>
            <camera_name>camera</camera_name>
            <frame_name>camera_link</frame_name>
            <hack_baseline>0.07</hack_baseline>
            <min_depth>0.2</min_depth>
          </plugin>
        </sensor>
        <pose relative_to='depth_camera::__model__'>0 0 0 0 -0 0</pose>
        <self_collide>0</self_collide>
        <enable_wind>0</enable_wind>
        <kinematic>0</kinematic>
      </link>
      <joint name='depth_camera_joint' type='revolute'>
        <child>depth_camera::link</child>
        <parent>base_link</parent>
        <axis>
          <xyz>0 0 1</xyz>
          <limit>
            <upper>0</upper>
            <lower>0</lower>
          </limit>
          <dynamics>
            <spring_reference>0</spring_reference>
            <spring_stiffness>0</spring_stiffness>
          </dynamics>
        </axis>
      </joint>
      <plugin name='rosbag' filename='libgazebo_multirotor_base_plugin.so'>
        <robotNamespace/>
        <linkName>base_link</linkName>
        <rotorVelocitySlowdownSim>10</rotorVelocitySlowdownSim>
      </plugin>
      <plugin name='front_right_motor_model' filename='libgazebo_motor_model.so'>
        <robotNamespace/>
        <jointName>rotor_0_joint</jointName>
        <linkName>rotor_0</linkName>
        <turningDirection>ccw</turningDirection>
        <timeConstantUp>0.0125</timeConstantUp>
        <timeConstantDown>0.025</timeConstantDown>
        <maxRotVelocity>1100</maxRotVelocity>
        <motorConstant>8.54858e-06</motorConstant>
        <momentConstant>0.06</momentConstant>
        <commandSubTopic>/gazebo/command/motor_speed</commandSubTopic>
        <motorNumber>0</motorNumber>
        <rotorDragCoefficient>0.000806428</rotorDragCoefficient>
        <rollingMomentCoefficient>1e-06</rollingMomentCoefficient>
        <motorSpeedPubTopic>/motor_speed/0</motorSpeedPubTopic>
        <rotorVelocitySlowdownSim>10</rotorVelocitySlowdownSim>
      </plugin>
      <plugin name='back_left_motor_model' filename='libgazebo_motor_model.so'>
        <robotNamespace/>
        <jointName>rotor_1_joint</jointName>
        <linkName>rotor_1</linkName>
        <turningDirection>ccw</turningDirection>
        <timeConstantUp>0.0125</timeConstantUp>
        <timeConstantDown>0.025</timeConstantDown>
        <maxRotVelocity>1100</maxRotVelocity>
        <motorConstant>8.54858e-06</motorConstant>
        <momentConstant>0.06</momentConstant>
        <commandSubTopic>/gazebo/command/motor_speed</commandSubTopic>
        <motorNumber>1</motorNumber>
        <rotorDragCoefficient>0.000806428</rotorDragCoefficient>
        <rollingMomentCoefficient>1e-06</rollingMomentCoefficient>
        <motorSpeedPubTopic>/motor_speed/1</motorSpeedPubTopic>
        <rotorVelocitySlowdownSim>10</rotorVelocitySlowdownSim>
      </plugin>
      <plugin name='front_left_motor_model' filename='libgazebo_motor_model.so'>
        <robotNamespace/>
        <jointName>rotor_2_joint</jointName>
        <linkName>rotor_2</linkName>
        <turningDirection>cw</turningDirection>
        <timeConstantUp>0.0125</timeConstantUp>
        <timeConstantDown>0.025</timeConstantDown>
        <maxRotVelocity>1100</maxRotVelocity>
        <motorConstant>8.54858e-06</motorConstant>
        <momentConstant>0.06</momentConstant>
        <commandSubTopic>/gazebo/command/motor_speed</commandSubTopic>
        <motorNumber>2</motorNumber>
        <rotorDragCoefficient>0.000806428</rotorDragCoefficient>
        <rollingMomentCoefficient>1e-06</rollingMomentCoefficient>
        <motorSpeedPubTopic>/motor_speed/2</motorSpeedPubTopic>
        <rotorVelocitySlowdownSim>10</rotorVelocitySlowdownSim>
      </plugin>
      <plugin name='back_right_motor_model' filename='libgazebo_motor_model.so'>
        <robotNamespace/>
        <jointName>rotor_3_joint</jointName>
        <linkName>rotor_3</linkName>
        <turningDirection>cw</turningDirection>
        <timeConstantUp>0.0125</timeConstantUp>
        <timeConstantDown>0.025</timeConstantDown>
        <maxRotVelocity>1100</maxRotVelocity>
        <motorConstant>8.54858e-06</motorConstant>
        <momentConstant>0.06</momentConstant>
        <commandSubTopic>/gazebo/command/motor_speed</commandSubTopic>
        <motorNumber>3</motorNumber>
        <rotorDragCoefficient>0.000806428</rotorDragCoefficient>
        <rollingMomentCoefficient>1e-06</rollingMomentCoefficient>
        <motorSpeedPubTopic>/motor_speed/3</motorSpeedPubTopic>
        <rotorVelocitySlowdownSim>10</rotorVelocitySlowdownSim>
      </plugin>
      <plugin name='groundtruth_plugin' filename='libgazebo_groundtruth_plugin.so'>
        <robotNamespace/>
      </plugin>
      <plugin name='magnetometer_plugin' filename='libgazebo_magnetometer_plugin.so'>
        <robotNamespace/>
        <pubRate>20</pubRate>
        <noiseDensity>0.0004</noiseDensity>
        <randomWalk>6.4e-06</randomWalk>
        <biasCorrelationTime>600</biasCorrelationTime>
        <magTopic>/mag</magTopic>
      </plugin>
      <plugin name='barometer_plugin' filename='libgazebo_barometer_plugin.so'>
        <robotNamespace/>
        <pubRate>10</pubRate>
        <baroTopic>/baro</baroTopic>
      </plugin>
      <plugin name='mavlink_interface' filename='libgazebo_mavlink_interface.so'>
        <robotNamespace/>
        <imuSubTopic>/imu</imuSubTopic>
        <gpsSubTopic>/gps</gpsSubTopic>
        <magSubTopic>/mag</magSubTopic>
        <baroSubTopic>/baro</baroSubTopic>
        <mavlink_addr>INADDR_ANY</mavlink_addr>
        <mavlink_udp_port>14560</mavlink_udp_port>
        <mavlink_tcp_port>4560</mavlink_tcp_port>
        <serialEnabled>0</serialEnabled>
        <serialDevice>/dev/ttyACM0</serialDevice>
        <baudRate>921600</baudRate>
        <qgc_addr>INADDR_ANY</qgc_addr>
        <qgc_udp_port>14550</qgc_udp_port>
        <sdk_addr>INADDR_ANY</sdk_addr>
        <sdk_udp_port>14540</sdk_udp_port>
        <hil_mode>0</hil_mode>
        <hil_state_level>0</hil_state_level>
        <send_vision_estimation>1</send_vision_estimation>
        <send_odometry>0</send_odometry>
        <enable_lockstep>1</enable_lockstep>
        <use_tcp>1</use_tcp>
        <motorSpeedCommandPubTopic>/gazebo/command/motor_speed</motorSpeedCommandPubTopic>
        <control_channels>
          <channel name='rotor1'>
            <input_index>0</input_index>
            <input_offset>0</input_offset>
            <input_scaling>1000</input_scaling>
            <zero_position_disarmed>0</zero_position_disarmed>
            <zero_position_armed>100</zero_position_armed>
            <joint_control_type>velocity</joint_control_type>
          </channel>
          <channel name='rotor2'>
            <input_index>1</input_index>
            <input_offset>0</input_offset>
            <input_scaling>1000</input_scaling>
            <zero_position_disarmed>0</zero_position_disarmed>
            <zero_position_armed>100</zero_position_armed>
            <joint_control_type>velocity</joint_control_type>
          </channel>
          <channel name='rotor3'>
            <input_index>2</input_index>
            <input_offset>0</input_offset>
            <input_scaling>1000</input_scaling>
            <zero_position_disarmed>0</zero_position_disarmed>
            <zero_position_armed>100</zero_position_armed>
            <joint_control_type>velocity</joint_control_type>
          </channel>
          <channel name='rotor4'>
            <input_index>3</input_index>
            <input_offset>0</input_offset>
            <input_scaling>1000</input_scaling>
            <zero_position_disarmed>0</zero_position_disarmed>
            <zero_position_armed>100</zero_position_armed>
            <joint_control_type>velocity</joint_control_type>
          </channel>
          <channel name='rotor5'>
            <input_index>4</input_index>
            <input_offset>1</input_offset>
            <input_scaling>324.6</input_scaling>
            <zero_position_disarmed>0</zero_position_disarmed>
            <zero_position_armed>0</zero_position_armed>
            <joint_control_type>velocity</joint_control_type>
            <joint_control_pid>
              <p>0.1</p>
              <i>0</i>
              <d>0</d>
              <iMax>0.0</iMax>
              <iMin>0.0</iMin>
              <cmdMax>2</cmdMax>
              <cmdMin>-2</cmdMin>
            </joint_control_pid>
            <joint_name>zephyr_delta_wing::propeller_joint</joint_name>
          </channel>
          <channel name='rotor6'>
            <input_index>5</input_index>
            <input_offset>0</input_offset>
            <input_scaling>0.524</input_scaling>
            <zero_position_disarmed>0</zero_position_disarmed>
            <zero_position_armed>0</zero_position_armed>
            <joint_control_type>position</joint_control_type>
            <joint_name>zephyr_delta_wing::flap_left_joint</joint_name>
            <joint_control_pid>
              <p>10.0</p>
              <i>0</i>
              <d>0</d>
              <iMax>0</iMax>
              <iMin>0</iMin>
              <cmdMax>20</cmdMax>
              <cmdMin>-20</cmdMin>
            </joint_control_pid>
          </channel>
          <channel name='rotor7'>
            <input_index>6</input_index>
            <input_offset>0</input_offset>
            <input_scaling>0.524</input_scaling>
            <zero_position_disarmed>0</zero_position_disarmed>
            <zero_position_armed>0</zero_position_armed>
            <joint_control_type>position</joint_control_type>
            <joint_name>zephyr_delta_wing::flap_right_joint</joint_name>
            <joint_control_pid>
              <p>10.0</p>
              <i>0</i>
              <d>0</d>
              <iMax>0</iMax>
              <iMin>0</iMin>
              <cmdMax>20</cmdMax>
              <cmdMin>-20</cmdMin>
            </joint_control_pid>
          </channel>
          <channel name='rotor8'>
            <input_index>7</input_index>
            <input_offset>0</input_offset>
            <input_scaling>0.524</input_scaling>
            <zero_position_disarmed>0</zero_position_disarmed>
            <zero_position_armed>0</zero_position_armed>
            <joint_control_type>position</joint_control_type>
          </channel>
        </control_channels>
      </plugin>
      <static>0</static>
      <plugin name='rotors_gazebo_imu_plugin' filename='libgazebo_imu_plugin.so'>
        <robotNamespace/>
        <linkName>/imu_link</linkName>
        <imuTopic>/imu</imuTopic>
        <gyroscopeNoiseDensity>0.00018665</gyroscopeNoiseDensity>
        <gyroscopeRandomWalk>3.8785e-05</gyroscopeRandomWalk>
        <gyroscopeBiasCorrelationTime>1000.0</gyroscopeBiasCorrelationTime>
        <gyroscopeTurnOnBiasSigma>0.0087</gyroscopeTurnOnBiasSigma>
        <accelerometerNoiseDensity>0.00186</accelerometerNoiseDensity>
        <accelerometerRandomWalk>0.006</accelerometerRandomWalk>
        <accelerometerBiasCorrelationTime>300.0</accelerometerBiasCorrelationTime>
        <accelerometerTurnOnBiasSigma>0.196</accelerometerTurnOnBiasSigma>
      </plugin>
      <pose>2.99873 -17.7237 0.294933 0 -0 1.57</pose>
    </model>
    <model name='rover_proto_A1_gps'>
      <link name='Chassis'>
        <inertial>
          <pose>-0.003619 -4e-06 -0.025333 0 -0 0</pose>
          <mass>18.0939</mass>
          <inertia>
            <ixx>0.190571</ixx>
            <ixy>-3.70556e-06</ixy>
            <ixz>0.00402842</ixz>
            <iyy>1.55584</iyy>
            <iyz>-8.33164e-06</iyz>
            <izz>1.731</izz>
          </inertia>
        </inertial>
        <collision name='Chassis_collision'>
          <pose>0 0 0 0 -0 0</pose>
          <geometry>
            <mesh>
              <scale>1 1 1</scale>
              <uri>model://line_following_rover/urdf/rover_proto_A1/meshes/Chassis.STL</uri>
            </mesh>
          </geometry>
          <max_contacts>10</max_contacts>
          <surface>
            <contact>
              <ode/>
            </contact>
            <bounce/>
            <friction>
              <torsional>
                <ode/>
              </torsional>
              <ode/>
            </friction>
          </surface>
        </collision>
        <collision name='Chassis_fixed_joint_lump__Camera_Back_Link_collision_1'>
          <pose>-0.50128 0 0.046965 0 -0 0</pose>
          <geometry>
            <mesh>
              <scale>1 1 1</scale>
              <uri>model://line_following_rover/urdf/rover_proto_A1/meshes/Camera_Back_Link.STL</uri>
            </mesh>
          </geometry>
          <max_contacts>10</max_contacts>
          <surface>
            <contact>
              <ode/>
            </contact>
            <bounce/>
            <friction>
              <torsional>
                <ode/>
              </torsional>
              <ode/>
            </friction>
          </surface>
        </collision>
        <collision name='Chassis_fixed_joint_lump__Camera_Fwd_Link_collision_2'>
          <pose>0.49872 0 0.046965 0 -0 0</pose>
          <geometry>
            <mesh>
              <scale>1 1 1</scale>
              <uri>model://line_following_rover/urdf/rover_proto_A1/meshes/Camera_Fwd_Link.STL</uri>
            </mesh>
          </geometry>
          <surface>
            <contact>
              <ode/>
            </contact>
            <friction>
              <ode/>
              <torsional>
                <ode/>
              </torsional>
            </friction>
            <bounce/>
          </surface>
          <max_contacts>10</max_contacts>
        </collision>
        <collision name='Chassis_fixed_joint_lump__Lidar_Back_Link_collision_3'>
          <pose>-0.34128 0 0.166 0 -0 1.57</pose>
          <geometry>
            <mesh>
              <scale>1 1 1</scale>
              <uri>model://line_following_rover/urdf/rover_proto_A1/meshes/Lidar_Back_Link.STL</uri>
            </mesh>
          </geometry>
          <surface>
            <contact>
              <ode/>
            </contact>
            <friction>
              <ode/>
              <torsional>
                <ode/>
              </torsional>
            </friction>
            <bounce/>
          </surface>
          <max_contacts>10</max_contacts>
        </collision>
        <collision name='Chassis_fixed_joint_lump__Lidar_Fwd_Link_collision_4'>
          <pose>0.33872 0 0.116 0 0 -1.57</pose>
          <geometry>
            <mesh>
              <scale>1 1 1</scale>
              <uri>model://line_following_rover/urdf/rover_proto_A1/meshes/Lidar_Fwd_Link.STL</uri>
            </mesh>
          </geometry>
          <surface>
            <contact>
              <ode/>
            </contact>
            <friction>
              <ode/>
              <torsional>
                <ode/>
              </torsional>
            </friction>
            <bounce/>
          </surface>
          <max_contacts>10</max_contacts>
        </collision>
        <collision name='Chassis_fixed_joint_lump__Lights_Back_Link_collision_5'>
          <pose>0 0 0 0 -0 0</pose>
          <geometry>
            <mesh>
              <scale>1 1 1</scale>
              <uri>model://line_following_rover/urdf/rover_proto_A1/meshes/Lights_Back_Link.STL</uri>
            </mesh>
          </geometry>
          <max_contacts>10</max_contacts>
          <surface>
            <contact>
              <ode/>
            </contact>
            <bounce/>
            <friction>
              <torsional>
                <ode/>
              </torsional>
              <ode/>
            </friction>
          </surface>
        </collision>
        <collision name='Chassis_fixed_joint_lump__Lights_Fwd_Link_collision_6'>
          <pose>0 0 0 0 -0 0</pose>
          <geometry>
            <mesh>
              <scale>1 1 1</scale>
              <uri>model://line_following_rover/urdf/rover_proto_A1/meshes/Lights_Fwd_Link.STL</uri>
            </mesh>
          </geometry>
          <max_contacts>10</max_contacts>
          <surface>
            <contact>
              <ode/>
            </contact>
            <bounce/>
            <friction>
              <torsional>
                <ode/>
              </torsional>
              <ode/>
            </friction>
          </surface>
        </collision>
        <collision name='Chassis_fixed_joint_lump__Lights_Left_Link_collision_7'>
          <pose>0 0 0 0 -0 0</pose>
          <geometry>
            <mesh>
              <scale>1 1 1</scale>
              <uri>model://line_following_rover/urdf/rover_proto_A1/meshes/Lights_Left_Link.STL</uri>
            </mesh>
          </geometry>
          <max_contacts>10</max_contacts>
          <surface>
            <contact>
              <ode/>
            </contact>
            <bounce/>
            <friction>
              <torsional>
                <ode/>
              </torsional>
              <ode/>
            </friction>
          </surface>
        </collision>
        <collision name='Chassis_fixed_joint_lump__Lights_Right_Link_collision_8'>
          <pose>0 0 0 0 -0 0</pose>
          <geometry>
            <mesh>
              <scale>1 1 1</scale>
              <uri>model://line_following_rover/urdf/rover_proto_A1/meshes/Lights_Right_Link.STL</uri>
            </mesh>
          </geometry>
          <max_contacts>10</max_contacts>
          <surface>
            <contact>
              <ode/>
            </contact>
            <bounce/>
            <friction>
              <torsional>
                <ode/>
              </torsional>
              <ode/>
            </friction>
          </surface>
        </collision>
        <collision name='Chassis_fixed_joint_lump__link_GPS_collision_9'>
          <pose>0 0 -0.01 0 -0 0</pose>
          <geometry>
            <cylinder>
              <length>0.02</length>
              <radius>0.02</radius>
            </cylinder>
          </geometry>
          <surface>
            <contact>
              <ode/>
            </contact>
            <friction>
              <ode/>
              <torsional>
                <ode/>
              </torsional>
            </friction>
            <bounce/>
          </surface>
          <max_contacts>10</max_contacts>
        </collision>
        <visual name='Chassis_visual'>
          <pose>0 0 0 0 -0 0</pose>
          <geometry>
            <mesh>
              <scale>1 1 1</scale>
              <uri>model://line_following_rover/urdf/rover_proto_A1/meshes/Chassis.dae</uri>
            </mesh>
          </geometry>
        </visual>
        <visual name='Chassis_fixed_joint_lump__Camera_Back_Link_visual_1'>
          <pose>-0.50128 0 0.046965 0 -0 0</pose>
          <geometry>
            <mesh>
              <scale>1 1 1</scale>
              <uri>model://line_following_rover/urdf/rover_proto_A1/meshes/Camera_Back_Link.dae</uri>
            </mesh>
          </geometry>
        </visual>
        <visual name='Chassis_fixed_joint_lump__Camera_Fwd_Link_visual_2'>
          <pose>0.49872 0 0.046965 0 -0 0</pose>
          <geometry>
            <mesh>
              <scale>1 1 1</scale>
              <uri>model://line_following_rover/urdf/rover_proto_A1/meshes/Camera_Fwd_Link.STL</uri>
            </mesh>
          </geometry>
          <material>
            <script>
              <name>Gazebo/Blue</name>
              <uri>file://media/materials/scripts/gazebo.material</uri>
            </script>
          </material>
        </visual>
        <visual name='Chassis_fixed_joint_lump__Lidar_Back_Link_visual_3'>
          <pose>-0.34128 0 0.166 0 -0 1.57</pose>
          <geometry>
            <mesh>
              <scale>1 1 1</scale>
              <uri>model://line_following_rover/urdf/rover_proto_A1/meshes/Lidar_Back_Link.STL</uri>
            </mesh>
          </geometry>
          <material>
            <script>
              <name>Gazebo/Red</name>
              <uri>file://media/materials/scripts/gazebo.material</uri>
            </script>
          </material>
        </visual>
        <visual name='Chassis_fixed_joint_lump__Lidar_Fwd_Link_visual_4'>
          <pose>0.33872 0 0.116 0 0 -1.57</pose>
          <geometry>
            <mesh>
              <scale>1 1 1</scale>
              <uri>model://line_following_rover/urdf/rover_proto_A1/meshes/Lidar_Fwd_Link.STL</uri>
            </mesh>
          </geometry>
          <material>
            <script>
              <name>Gazebo/Red</name>
              <uri>file://media/materials/scripts/gazebo.material</uri>
            </script>
          </material>
        </visual>
        <visual name='Chassis_fixed_joint_lump__Lights_Back_Link_visual_5'>
          <pose>0 0 0 0 -0 0</pose>
          <geometry>
            <mesh>
              <scale>1 1 1</scale>
              <uri>model://line_following_rover/urdf/rover_proto_A1/meshes/Lights_Back_Link.STL</uri>
            </mesh>
          </geometry>
        </visual>
        <visual name='Chassis_fixed_joint_lump__Lights_Fwd_Link_visual_6'>
          <pose>0 0 0 0 -0 0</pose>
          <geometry>
            <mesh>
              <scale>1 1 1</scale>
              <uri>model://line_following_rover/urdf/rover_proto_A1/meshes/Lights_Fwd_Link.STL</uri>
            </mesh>
          </geometry>
        </visual>
        <visual name='Chassis_fixed_joint_lump__Lights_Left_Link_visual_7'>
          <pose>0 0 0 0 -0 0</pose>
          <geometry>
            <mesh>
              <scale>1 1 1</scale>
              <uri>model://line_following_rover/urdf/rover_proto_A1/meshes/Lights_Left_Link.STL</uri>
            </mesh>
          </geometry>
        </visual>
        <visual name='Chassis_fixed_joint_lump__Lights_Right_Link_visual_8'>
          <pose>0 0 0 0 -0 0</pose>
          <geometry>
            <mesh>
              <scale>1 1 1</scale>
              <uri>model://line_following_rover/urdf/rover_proto_A1/meshes/Lights_Right_Link.STL</uri>
            </mesh>
          </geometry>
        </visual>
        <visual name='Chassis_fixed_joint_lump__link_GPS_visual_9'>
          <pose>0 0 -0.01 0 -0 0</pose>
          <geometry>
            <cylinder>
              <length>0.02</length>
              <radius>0.02</radius>
            </cylinder>
          </geometry>
        </visual>
        <sensor name='camera_scan_back' type='camera'>
          <visualize>1</visualize>
          <update_rate>30</update_rate>
          <camera name='cam_back'>
            <horizontal_fov>1.39626</horizontal_fov>
            <image>
              <width>800</width>
              <height>800</height>
              <format>R8G8B8</format>
            </image>
            <clip>
              <near>0.02</near>
              <far>300</far>
            </clip>
            <noise>
              <type>gaussian</type>
              <mean>0</mean>
              <stddev>0.007</stddev>
            </noise>
          </camera>
          <plugin name='camera_driver_bck' filename='libgazebo_ros_camera.so'>
            <updateRate>0.0</updateRate>
            <cameraName>/camera_back</cameraName>
            <imageTopicName>image_raw</imageTopicName>
            <cameraInfoTopicName>camera_info</cameraInfoTopicName>
            <frameName>Camera_Back_Link_Frame</frameName>
            <hackBaseline>0.07</hackBaseline>
          </plugin>
          <pose>-0.50128 0 0.046965 0 -0 -3.14159</pose>
          <alwaysOn>1</alwaysOn>
        </sensor>
        <sensor name='camera_scan_fwd' type='camera'>
          <visualize>1</visualize>
          <update_rate>30</update_rate>
          <camera name='cam_fwd'>
            <horizontal_fov>1.39626</horizontal_fov>
            <image>
              <width>800</width>
              <height>800</height>
              <format>R8G8B8</format>
            </image>
            <clip>
              <near>0.02</near>
              <far>300</far>
            </clip>
            <noise>
              <type>gaussian</type>
              <mean>0</mean>
              <stddev>0.007</stddev>
            </noise>
          </camera>
          <plugin name='camera_driver_fwd' filename='libgazebo_ros_camera.so'>
            <updateRate>0.0</updateRate>
            <cameraName>/camera_fwd</cameraName>
            <imageTopicName>image_raw</imageTopicName>
            <cameraInfoTopicName>camera_info</cameraInfoTopicName>
            <frameName>Camera_Fwd_Link</frameName>
            <hackBaseline>0.07</hackBaseline>
          </plugin>
          <pose>0.49872 0 0.046965 0 -0 0</pose>
          <alwaysOn>1</alwaysOn>
        </sensor>
        <sensor name='gazebo_lidar_back' type='ray'>
          <visualize>1</visualize>
          <update_rate>12</update_rate>
          <plugin name='gazebo_lidar_back' filename='libgazebo_ros_ray_sensor.so'>
            <ros>
              <remapping>~/out:=lidar_scan_back</remapping>
            </ros>
            <output_type>sensor_msgs/LaserScan</output_type>
            <frame_name>Lidar_Back_Link</frame_name>
          </plugin>
          <ray>
            <scan>
              <horizontal>
                <samples>360</samples>
                <resolution>1</resolution>
                <min_angle>0</min_angle>
                <max_angle>3.14</max_angle>
              </horizontal>
              <vertical>
                <samples>1</samples>
                <min_angle>0</min_angle>
                <max_angle>0</max_angle>
              </vertical>
            </scan>
            <range>
              <min>0.12</min>
              <max>3.5</max>
              <resolution>0.015</resolution>
            </range>
            <noise>
              <type>gaussian</type>
              <mean>0</mean>
              <stddev>0.01</stddev>
            </noise>
          </ray>
          <pose>-0.34128 0 0.166 0 -0 1.57</pose>
        </sensor>
        <sensor name='gazebo_lidar_fwd' type='ray'>
          <visualize>1</visualize>
          <update_rate>12</update_rate>
          <plugin name='gazebo_lidar_fwd' filename='libgazebo_ros_ray_sensor.so'>
            <ros>
              <remapping>~/out:=lidar_scan_fwd</remapping>
            </ros>
            <output_type>sensor_msgs/LaserScan</output_type>
            <frame_name>Lidar_Fwd_Link</frame_name>
          </plugin>
          <ray>
            <scan>
              <horizontal>
                <samples>360</samples>
                <resolution>1</resolution>
                <min_angle>0</min_angle>
                <max_angle>3.14</max_angle>
              </horizontal>
              <vertical>
                <samples>1</samples>
                <min_angle>0</min_angle>
                <max_angle>0</max_angle>
              </vertical>
            </scan>
            <range>
              <min>0.12</min>
              <max>3.5</max>
              <resolution>0.015</resolution>
            </range>
            <noise>
              <type>gaussian</type>
              <mean>0</mean>
              <stddev>0.01</stddev>
            </noise>
          </ray>
          <pose>0.33872 0 0.116 0 0 -1.57</pose>
        </sensor>
        <sensor name='gps_rover' type='gps'>
          <update_rate>30</update_rate>
          <always_on>1</always_on>
          <visualize>0</visualize>
          <plugin name='gps_rover_plugin' filename='libgazebo_ros_gps_sensor.so'>
            <ros>
              <namespace>/gps</namespace>
              <remapping>~/out:=rover_gps_data</remapping>
            </ros>
            <bodyName>link_GPS</bodyName>
            <frameId>link_GPS</frameId>
            <topicName>/gps/fix</topicName>
            <velocityTopicName>/gps/fix_velocity</velocityTopicName>
            <referenceLatitude>-30.06022459407145675</referenceLatitude>
            <referenceLongitude>-51.173913575780311191</referenceLongitude>
            <referenceHeading>90</referenceHeading>
            <referenceAltitude>10</referenceAltitude>
            <offset>0 0 0</offset>
            <drift>0.001 0.001 0.001</drift>
            <gaussianNoise>0.05 0.05 0.05</gaussianNoise>
            <velocityDrift>0.001 0.001 0.001</velocityDrift>
            <velocityGaussianNoise>0.5 0.5 0.5</velocityGaussianNoise>
            <debug>1</debug>
          </plugin>
          <pose>0 0 -0.01 0 -0 0</pose>
          <gps/>
        </sensor>
        <self_collide>0</self_collide>
        <enable_wind>0</enable_wind>
        <kinematic>0</kinematic>
      </link>
      <joint name='Wheel_1_Joint' type='revolute'>
        <pose relative_to='Chassis'>0.34872 -0.215 -0.04 1.5708 -0 0</pose>
        <parent>Chassis</parent>
        <child>Wheel_1_Link</child>
        <axis>
          <xyz>0 0 -1</xyz>
          <limit>
            <effort>10</effort>
            <velocity>12</velocity>
            <lower>-1e+16</lower>
            <upper>1e+16</upper>
          </limit>
          <dynamics>
            <damping>0.25</damping>
            <friction>0.5</friction>
            <spring_reference>0</spring_reference>
            <spring_stiffness>0</spring_stiffness>
          </dynamics>
        </axis>
      </joint>
      <link name='Wheel_1_Link'>
        <pose relative_to='Wheel_1_Joint'>0 0 0 0 -0 0</pose>
        <inertial>
          <pose>0 -0 -0.016853 0 -0 0</pose>
          <mass>0.456818</mass>
          <inertia>
            <ixx>0.000768197</ixx>
            <ixy>4.1359e-21</ixy>
            <ixz>-4.91914e-19</ixz>
            <iyy>0.000768197</iyy>
            <iyz>2.33003e-19</iyz>
            <izz>0.00134492</izz>
          </inertia>
        </inertial>
        <collision name='Wheel_1_Link_collision'>
          <pose>0 0 0 0 -0 0</pose>
          <geometry>
            <mesh>
              <scale>1 1 1</scale>
              <uri>model://line_following_rover/urdf/rover_proto_A1/meshes/Wheel_1_Link.STL</uri>
            </mesh>
          </geometry>
          <max_contacts>10</max_contacts>
          <surface>
            <contact>
              <ode/>
            </contact>
            <bounce/>
            <friction>
              <torsional>
                <ode/>
              </torsional>
              <ode/>
            </friction>
          </surface>
        </collision>
        <visual name='Wheel_1_Link_visual'>
          <pose>0 0 0 0 -0 0</pose>
          <geometry>
            <mesh>
              <scale>1 1 1</scale>
              <uri>model://line_following_rover/urdf/rover_proto_A1/meshes/Wheel_1_Link.STL</uri>
            </mesh>
          </geometry>
        </visual>
        <self_collide>0</self_collide>
        <enable_wind>0</enable_wind>
        <kinematic>0</kinematic>
      </link>
      <joint name='Wheel_2_Joint' type='revolute'>
        <pose relative_to='Chassis'>0.34872 0.215 -0.04 1.5708 -0 0</pose>
        <parent>Chassis</parent>
        <child>Wheel_2_Link</child>
        <axis>
          <xyz>0 0 -1</xyz>
          <limit>
            <effort>10</effort>
            <velocity>12</velocity>
            <lower>-1e+16</lower>
            <upper>1e+16</upper>
          </limit>
          <dynamics>
            <damping>0.25</damping>
            <friction>0.5</friction>
            <spring_reference>0</spring_reference>
            <spring_stiffness>0</spring_stiffness>
          </dynamics>
        </axis>
      </joint>
      <link name='Wheel_2_Link'>
        <pose relative_to='Wheel_2_Joint'>0 0 0 0 -0 0</pose>
        <inertial>
          <pose>-0 0 0.016853 0 -0 0</pose>
          <mass>0.456818</mass>
          <inertia>
            <ixx>0.000768197</ixx>
            <ixy>1.02115e-18</ixy>
            <ixz>-7.60711e-19</ixz>
            <iyy>0.000768197</iyy>
            <iyz>3.64043e-19</iyz>
            <izz>0.00134492</izz>
          </inertia>
        </inertial>
        <collision name='Wheel_2_Link_collision'>
          <pose>0 0 0 0 -0 0</pose>
          <geometry>
            <mesh>
              <scale>1 1 1</scale>
              <uri>model://line_following_rover/urdf/rover_proto_A1/meshes/Wheel_2_Link.STL</uri>
            </mesh>
          </geometry>
          <max_contacts>10</max_contacts>
          <surface>
            <contact>
              <ode/>
            </contact>
            <bounce/>
            <friction>
              <torsional>
                <ode/>
              </torsional>
              <ode/>
            </friction>
          </surface>
        </collision>
        <visual name='Wheel_2_Link_visual'>
          <pose>0 0 0 0 -0 0</pose>
          <geometry>
            <mesh>
              <scale>1 1 1</scale>
              <uri>model://line_following_rover/urdf/rover_proto_A1/meshes/Wheel_2_Link.STL</uri>
            </mesh>
          </geometry>
        </visual>
        <self_collide>0</self_collide>
        <enable_wind>0</enable_wind>
        <kinematic>0</kinematic>
      </link>
      <joint name='Wheel_3_Joint' type='revolute'>
        <pose relative_to='Chassis'>-0.35128 0.21499 -0.04 1.5708 -0 0</pose>
        <parent>Chassis</parent>
        <child>Wheel_3_Link</child>
        <axis>
          <xyz>0 0 -1</xyz>
          <limit>
            <effort>10</effort>
            <velocity>12</velocity>
            <lower>-1e+16</lower>
            <upper>1e+16</upper>
          </limit>
          <dynamics>
            <damping>0.25</damping>
            <friction>0.5</friction>
            <spring_reference>0</spring_reference>
            <spring_stiffness>0</spring_stiffness>
          </dynamics>
        </axis>
      </joint>
      <link name='Wheel_3_Link'>
        <pose relative_to='Wheel_3_Joint'>0 0 0 0 -0 0</pose>
        <inertial>
          <pose>-0 -0 0.016853 0 -0 0</pose>
          <mass>0.456818</mass>
          <inertia>
            <ixx>0.000768197</ixx>
            <ixy>-1.88597e-19</ixy>
            <ixz>-4.93382e-19</ixz>
            <iyy>0.000768197</iyy>
            <iyz>-2.11063e-19</iyz>
            <izz>0.00134492</izz>
          </inertia>
        </inertial>
        <collision name='Wheel_3_Link_collision'>
          <pose>0 0 0 0 -0 0</pose>
          <geometry>
            <mesh>
              <scale>1 1 1</scale>
              <uri>model://line_following_rover/urdf/rover_proto_A1/meshes/Wheel_3_Link.STL</uri>
            </mesh>
          </geometry>
          <max_contacts>10</max_contacts>
          <surface>
            <contact>
              <ode/>
            </contact>
            <bounce/>
            <friction>
              <torsional>
                <ode/>
              </torsional>
              <ode/>
            </friction>
          </surface>
        </collision>
        <visual name='Wheel_3_Link_visual'>
          <pose>0 0 0 0 -0 0</pose>
          <geometry>
            <mesh>
              <scale>1 1 1</scale>
              <uri>model://line_following_rover/urdf/rover_proto_A1/meshes/Wheel_3_Link.STL</uri>
            </mesh>
          </geometry>
        </visual>
        <self_collide>0</self_collide>
        <enable_wind>0</enable_wind>
        <kinematic>0</kinematic>
      </link>
      <joint name='Wheel_4_Joint' type='revolute'>
        <pose relative_to='Chassis'>-0.35128 -0.215 -0.04 1.5708 -0 0</pose>
        <parent>Chassis</parent>
        <child>Wheel_4_Link</child>
        <axis>
          <xyz>0 0 -1</xyz>
          <limit>
            <effort>10</effort>
            <velocity>12</velocity>
            <lower>-1e+16</lower>
            <upper>1e+16</upper>
          </limit>
          <dynamics>
            <damping>0.25</damping>
            <friction>0.5</friction>
            <spring_reference>0</spring_reference>
            <spring_stiffness>0</spring_stiffness>
          </dynamics>
        </axis>
      </joint>
      <link name='Wheel_4_Link'>
        <pose relative_to='Wheel_4_Joint'>0 0 0 0 -0 0</pose>
        <inertial>
          <pose>0 0 -0.016853 0 -0 0</pose>
          <mass>0.456818</mass>
          <inertia>
            <ixx>0.000768197</ixx>
            <ixy>-7.84271e-19</ixy>
            <ixz>-6.61935e-19</ixz>
            <iyy>0.000768197</iyy>
            <iyz>-2.6149e-19</iyz>
            <izz>0.00134492</izz>
          </inertia>
        </inertial>
        <collision name='Wheel_4_Link_collision'>
          <pose>0 0 0 0 -0 0</pose>
          <geometry>
            <mesh>
              <scale>1 1 1</scale>
              <uri>model://line_following_rover/urdf/rover_proto_A1/meshes/Wheel_4_Link.STL</uri>
            </mesh>
          </geometry>
          <max_contacts>10</max_contacts>
          <surface>
            <contact>
              <ode/>
            </contact>
            <bounce/>
            <friction>
              <torsional>
                <ode/>
              </torsional>
              <ode/>
            </friction>
          </surface>
        </collision>
        <visual name='Wheel_4_Link_visual'>
          <pose>0 0 0 0 -0 0</pose>
          <geometry>
            <mesh>
              <scale>1 1 1</scale>
              <uri>model://line_following_rover/urdf/rover_proto_A1/meshes/Wheel_4_Link.STL</uri>
            </mesh>
          </geometry>
        </visual>
        <self_collide>0</self_collide>
        <enable_wind>0</enable_wind>
        <kinematic>0</kinematic>
      </link>
      <static>0</static>
      <plugin name='diff_drive_fwd' filename='libgazebo_ros_diff_drive.so'>
        <left_joint>Wheel_2_Joint</left_joint>
        <right_joint>Wheel_1_Joint</right_joint>
        <wheel_separation>0.43</wheel_separation>
        <wheel_diameter>0.16</wheel_diameter>
        <max_wheel_torque>30</max_wheel_torque>
        <max_wheel_acceleration>1.50</max_wheel_acceleration>
        <publish_odom>1</publish_odom>
        <publish_odom_tf>1</publish_odom_tf>
        <publish_wheel_tf>1</publish_wheel_tf>
        <odometry_frame>base_footprint</odometry_frame>
        <robot_base_frame>Chassis</robot_base_frame>
      </plugin>
      <plugin name='diff_drive_back' filename='libgazebo_ros_diff_drive.so'>
        <left_joint>Wheel_3_Joint</left_joint>
        <right_joint>Wheel_4_Joint</right_joint>
        <wheel_separation>0.43</wheel_separation>
        <wheel_diameter>0.16</wheel_diameter>
        <max_wheel_torque>30</max_wheel_torque>
        <max_wheel_acceleration>1.50</max_wheel_acceleration>
        <publish_odom>1</publish_odom>
        <publish_odom_tf>1</publish_odom_tf>
        <publish_wheel_tf>1</publish_wheel_tf>
        <odometry_frame>base_footprint</odometry_frame>
        <robot_base_frame>Chassis</robot_base_frame>
      </plugin>
      <pose>0 0 0 0 -0 0</pose>
    </model>
  </world>
</sdf>
